// Higher-order function to catch async errors
export const catchAsync = fn => {
    return (req, res, next) => {
        fn(req, res, next).catch(next);
    };
}; 